<robot name="cinebot_rexarm">
  <link name="base_link">
    <visual>
      <origin xyz="0 0 0.036" rpy="0 0 0"/>
      <geometry>
        <box size="0.01 0.01 0.072"/>
      </geometry>
    </visual> 
  </link>
  <link name="link1">
    <visual>
      <origin xyz="0 0 0.0225" rpy="0 0 0"/>
      <geometry>
        <box size="0.01 0.01 0.045"/>
      </geometry>
    </visual> 
  </link>

  <link name="link2">
    <visual>
      <origin xyz="0 0 0.05" rpy="0 0 0"/>
      <geometry>
        <box size="0.01 0.01 0.1"/>
      </geometry>
    </visual> 
  </link>

  <link name="link3">
    <visual>
      <origin xyz="0 0 0.0335" rpy="0 0 0"/>
      <geometry>
        <box size="0.01 0.01 0.067"/>
      </geometry>
    </visual>
  </link>

  <link name="link4">
    <visual>
      <origin xyz="0 0 0.0235" rpy="0 0 0"/>
      <geometry>
        <box size="0.01 0.01 0.047"/>
      </geometry>
    </visual>
  </link>

  <link name="link5">
    <visual>
      <origin xyz="0 0 0.024" rpy="0 0 0"/>
      <geometry>
        <box size="0.01 0.01 0.048"/>
      </geometry>
    </visual>
  </link>

  <link name="link6">
    <visual>
      <origin xyz="0 0 0.009" rpy="0 0 0"/>
      <geometry>
        <box size="0.01 0.01 0.018"/>
      </geometry>
    </visual>
  </link>

  <joint name="joint0" type="revolute">
    <parent link="base_link"/>
    <child link="link1"/>
    <origin xyz="0 0 0.072" rpy="0 0 0" />
    <axis xyz="0 0 1" />
    <limit effort="30" velocity="1.0" lower="-3.14" upper="3.14" />
  </joint>

  <joint name="joint1" type="revolute">
    <parent link="link1"/>
    <child link="link2"/>
    <origin xyz="0 0 0.045" rpy="0 0 0" />
    <axis xyz="1 0 0" />
    <limit effort="30" velocity="1.0" lower="-2.18" upper="2.18" />
  </joint>

  <joint name="joint2" type="revolute">
    <parent link="link2"/>
    <child link="link3"/>
    <origin xyz="0 0 0.1" rpy="0 0 0" />
    <axis xyz="1 0 0" />
    <limit effort="30" velocity="1.0" lower="-2.09" upper="1.85" />
  </joint>

  <joint name="joint3" type="revolute">
    <parent link="link3"/>
    <child link="link4"/>
    <origin xyz="0 0 0.067" rpy="0 0 0" />
    <axis xyz="0 0 1" />
    <limit effort="30" velocity="1.0" lower="-2.61" upper="2.61" />
  </joint>

  <joint name="joint4" type="revolute">
    <parent link="link4"/>
    <child link="link5"/>
    <origin xyz="0 0 0.045" rpy="0 0 0" />
    <axis xyz="1 0 0" />
    <limit effort="30" velocity="1.0" lower="-1.83" upper="1.75" />
  </joint>

  <joint name="joint5" type="revolute">
    <parent link="link5"/>
    <child link="link6"/>
    <origin xyz="0 0 0.048" rpy="0 0 0" />
    <axis xyz="0 0 1" />
    <limit effort="30" velocity="1.0" lower="-2.61" upper="2.61" />
  </joint>
</robot>